[E 190119 14:35:56 KumNewServices:37] Error on create method of SysRolePrivilegeService
    Traceback (most recent call last):
      File "D:\pro\kump\modules\services\KumNewServices.py", line 32, in create
        objdb.topics.append(topic)
    AttributeError: 'KumNews' object has no attribute 'topics'
[E 190119 14:36:21 KumNewsController:35] (psycopg2.IntegrityError) null value in column "newsid" violates not-null constraint
    DETAIL:  Failing row contains (null, test44, tes, null, null, draft, null, 6).
     [SQL: 'INSERT INTO kum_news (newsid, title, content, created_date, created_by, status, isdeleted) VALUES (%(newsid)s, %(title)s, %(content)s, %(created_date)s, %(created_by)s, %(status)s, %(isdeleted)s) RETURNING kum_news.id'] [parameters: {'newsid': None, 'title': 'test44', 'content': 'tes', 'created_date': None, 'created_by': None, 'status': 'draft', 'isdeleted': None}] (Background on this error at: http://sqlalche.me/e/gkpj)
    Traceback (most recent call last):
      File "C:\Users\jeriy\.virtualenvs\kump\lib\site-packages\sqlalchemy\engine\base.py", line 1230, in _execute_context
        cursor, statement, parameters, context
      File "C:\Users\jeriy\.virtualenvs\kump\lib\site-packages\sqlalchemy\engine\default.py", line 536, in do_execute
        cursor.execute(statement, parameters)
    psycopg2.IntegrityError: null value in column "newsid" violates not-null constraint
    DETAIL:  Failing row contains (null, test44, tes, null, null, draft, null, 6).
    
    
    The above exception was the direct cause of the following exception:
    
    Traceback (most recent call last):
      File "D:\pro\kump\modules\controllers\KumNewsController.py", line 30, in post
        self.db_session.commit()
      File "C:\Users\jeriy\.virtualenvs\kump\lib\site-packages\sqlalchemy\orm\session.py", line 1008, in commit
        self.transaction.commit()
      File "C:\Users\jeriy\.virtualenvs\kump\lib\site-packages\sqlalchemy\orm\session.py", line 487, in commit
        self._prepare_impl()
      File "C:\Users\jeriy\.virtualenvs\kump\lib\site-packages\sqlalchemy\orm\session.py", line 466, in _prepare_impl
        self.session.flush()
      File "C:\Users\jeriy\.virtualenvs\kump\lib\site-packages\sqlalchemy\orm\session.py", line 2424, in flush
        self._flush(objects)
      File "C:\Users\jeriy\.virtualenvs\kump\lib\site-packages\sqlalchemy\orm\session.py", line 2562, in _flush
        transaction.rollback(_capture_exception=True)
      File "C:\Users\jeriy\.virtualenvs\kump\lib\site-packages\sqlalchemy\util\langhelpers.py", line 67, in __exit__
        compat.reraise(exc_type, exc_value, exc_tb)
      File "C:\Users\jeriy\.virtualenvs\kump\lib\site-packages\sqlalchemy\util\compat.py", line 277, in reraise
        raise value
      File "C:\Users\jeriy\.virtualenvs\kump\lib\site-packages\sqlalchemy\orm\session.py", line 2522, in _flush
        flush_context.execute()
      File "C:\Users\jeriy\.virtualenvs\kump\lib\site-packages\sqlalchemy\orm\unitofwork.py", line 416, in execute
        rec.execute(self)
      File "C:\Users\jeriy\.virtualenvs\kump\lib\site-packages\sqlalchemy\orm\unitofwork.py", line 583, in execute
        uow,
      File "C:\Users\jeriy\.virtualenvs\kump\lib\site-packages\sqlalchemy\orm\persistence.py", line 245, in save_obj
        insert,
      File "C:\Users\jeriy\.virtualenvs\kump\lib\site-packages\sqlalchemy\orm\persistence.py", line 1116, in _emit_insert_statements
        statement, params
      File "C:\Users\jeriy\.virtualenvs\kump\lib\site-packages\sqlalchemy\engine\base.py", line 974, in execute
        return meth(self, multiparams, params)
      File "C:\Users\jeriy\.virtualenvs\kump\lib\site-packages\sqlalchemy\sql\elements.py", line 273, in _execute_on_connection
        return connection._execute_clauseelement(self, multiparams, params)
      File "C:\Users\jeriy\.virtualenvs\kump\lib\site-packages\sqlalchemy\engine\base.py", line 1093, in _execute_clauseelement
        distilled_params,
      File "C:\Users\jeriy\.virtualenvs\kump\lib\site-packages\sqlalchemy\engine\base.py", line 1234, in _execute_context
        e, statement, parameters, cursor, context
      File "C:\Users\jeriy\.virtualenvs\kump\lib\site-packages\sqlalchemy\engine\base.py", line 1452, in _handle_dbapi_exception
        util.raise_from_cause(sqlalchemy_exception, exc_info)
      File "C:\Users\jeriy\.virtualenvs\kump\lib\site-packages\sqlalchemy\util\compat.py", line 296, in raise_from_cause
        reraise(type(exception), exception, tb=exc_tb, cause=cause)
      File "C:\Users\jeriy\.virtualenvs\kump\lib\site-packages\sqlalchemy\util\compat.py", line 276, in reraise
        raise value.with_traceback(tb)
      File "C:\Users\jeriy\.virtualenvs\kump\lib\site-packages\sqlalchemy\engine\base.py", line 1230, in _execute_context
        cursor, statement, parameters, context
      File "C:\Users\jeriy\.virtualenvs\kump\lib\site-packages\sqlalchemy\engine\default.py", line 536, in do_execute
        cursor.execute(statement, parameters)
    sqlalchemy.exc.IntegrityError: (psycopg2.IntegrityError) null value in column "newsid" violates not-null constraint
    DETAIL:  Failing row contains (null, test44, tes, null, null, draft, null, 6).
     [SQL: 'INSERT INTO kum_news (newsid, title, content, created_date, created_by, status, isdeleted) VALUES (%(newsid)s, %(title)s, %(content)s, %(created_date)s, %(created_by)s, %(status)s, %(isdeleted)s) RETURNING kum_news.id'] [parameters: {'newsid': None, 'title': 'test44', 'content': 'tes', 'created_date': None, 'created_by': None, 'status': 'draft', 'isdeleted': None}] (Background on this error at: http://sqlalche.me/e/gkpj)
